2021-05-13 09:55:03,391 [WARNING] Not Found: /favicon.ico
2021-05-13 12:09:00,870 [ERROR] Invalid HTTP_HOST header: '192.168.11.19:8000'. You may need to add '192.168.11.19' to ALLOWED_HOSTS.
2021-05-13 12:09:01,031 [WARNING] Bad Request: /
2021-05-13 13:56:49,006 [ERROR] Internal Server Error: /listmember/
Traceback (most recent call last):
  File "/usr/local/lib/python3.9/site-packages/django/core/handlers/exception.py", line 47, in inner
    response = get_response(request)
  File "/usr/local/lib/python3.9/site-packages/django/core/handlers/base.py", line 181, in _get_response
    response = wrapped_callback(request, *callback_args, **callback_kwargs)
  File "/home/il-piccola-0001/www/CheckPassword/./app/views.py", line 57, in listmember
    data = Member.objects.get(
AttributeError: 'Member' object has no attribute 'reverse'
2021-05-13 13:56:53,713 [ERROR] Internal Server Error: /listmember/
Traceback (most recent call last):
  File "/usr/local/lib/python3.9/site-packages/django/core/handlers/exception.py", line 47, in inner
    response = get_response(request)
  File "/usr/local/lib/python3.9/site-packages/django/core/handlers/base.py", line 181, in _get_response
    response = wrapped_callback(request, *callback_args, **callback_kwargs)
  File "/home/il-piccola-0001/www/CheckPassword/./app/views.py", line 57, in listmember
    data = Member.objects.get(
AttributeError: 'Member' object has no attribute 'reverse'
2021-05-13 13:57:50,368 [ERROR] Internal Server Error: /listmember/
Traceback (most recent call last):
  File "/usr/local/lib/python3.9/site-packages/django/core/handlers/exception.py", line 47, in inner
    response = get_response(request)
  File "/usr/local/lib/python3.9/site-packages/django/core/handlers/base.py", line 181, in _get_response
    response = wrapped_callback(request, *callback_args, **callback_kwargs)
  File "/home/il-piccola-0001/www/CheckPassword/./app/views.py", line 71, in listmember
    return render(request, 'listmember.html', params)
  File "/usr/local/lib/python3.9/site-packages/django/shortcuts.py", line 19, in render
    content = loader.render_to_string(template_name, context, request, using=using)
  File "/usr/local/lib/python3.9/site-packages/django/template/loader.py", line 62, in render_to_string
    return template.render(context, request)
  File "/usr/local/lib/python3.9/site-packages/django/template/backends/django.py", line 61, in render
    return self.template.render(context)
  File "/usr/local/lib/python3.9/site-packages/django/template/base.py", line 170, in render
    return self._render(context)
  File "/usr/local/lib/python3.9/site-packages/django/template/base.py", line 162, in _render
    return self.nodelist.render(context)
  File "/usr/local/lib/python3.9/site-packages/django/template/base.py", line 938, in render
    bit = node.render_annotated(context)
  File "/usr/local/lib/python3.9/site-packages/django/template/base.py", line 905, in render_annotated
    return self.render(context)
  File "/usr/local/lib/python3.9/site-packages/django/template/defaulttags.py", line 167, in render
    values = list(values)
TypeError: 'Member' object is not iterable
2021-05-13 14:43:15,606 [ERROR] Internal Server Error: /listmember/
Traceback (most recent call last):
  File "/usr/local/lib/python3.9/site-packages/django/db/backends/utils.py", line 84, in _execute
    return self.cursor.execute(sql, params)
  File "/usr/local/lib/python3.9/site-packages/django/db/backends/mysql/base.py", line 73, in execute
    return self.cursor.execute(query, args)
  File "/usr/local/lib/python3.9/site-packages/pymysql/cursors.py", line 148, in execute
    result = self._query(query)
  File "/usr/local/lib/python3.9/site-packages/pymysql/cursors.py", line 310, in _query
    conn.query(q)
  File "/usr/local/lib/python3.9/site-packages/pymysql/connections.py", line 548, in query
    self._affected_rows = self._read_query_result(unbuffered=unbuffered)
  File "/usr/local/lib/python3.9/site-packages/pymysql/connections.py", line 775, in _read_query_result
    result.read()
  File "/usr/local/lib/python3.9/site-packages/pymysql/connections.py", line 1156, in read
    first_packet = self.connection._read_packet()
  File "/usr/local/lib/python3.9/site-packages/pymysql/connections.py", line 725, in _read_packet
    packet.raise_for_error()
  File "/usr/local/lib/python3.9/site-packages/pymysql/protocol.py", line 221, in raise_for_error
    err.raise_mysql_exception(self._data)
  File "/usr/local/lib/python3.9/site-packages/pymysql/err.py", line 143, in raise_mysql_exception
    raise errorclass(errno, errval)
pymysql.err.ProgrammingError: (1146, "Table 'il-piccola-0001_checkpassword.app_member' doesn't exist")

The above exception was the direct cause of the following exception:

Traceback (most recent call last):
  File "/usr/local/lib/python3.9/site-packages/django/core/handlers/exception.py", line 47, in inner
    response = get_response(request)
  File "/usr/local/lib/python3.9/site-packages/django/core/handlers/base.py", line 181, in _get_response
    response = wrapped_callback(request, *callback_args, **callback_kwargs)
  File "/home/il-piccola-0001/www/CheckPassword/./app/views.py", line 55, in listmember
    return render(request, 'listmember.html', params)
  File "/usr/local/lib/python3.9/site-packages/django/shortcuts.py", line 19, in render
    content = loader.render_to_string(template_name, context, request, using=using)
  File "/usr/local/lib/python3.9/site-packages/django/template/loader.py", line 62, in render_to_string
    return template.render(context, request)
  File "/usr/local/lib/python3.9/site-packages/django/template/backends/django.py", line 61, in render
    return self.template.render(context)
  File "/usr/local/lib/python3.9/site-packages/django/template/base.py", line 170, in render
    return self._render(context)
  File "/usr/local/lib/python3.9/site-packages/django/template/base.py", line 162, in _render
    return self.nodelist.render(context)
  File "/usr/local/lib/python3.9/site-packages/django/template/base.py", line 938, in render
    bit = node.render_annotated(context)
  File "/usr/local/lib/python3.9/site-packages/django/template/base.py", line 905, in render_annotated
    return self.render(context)
  File "/usr/local/lib/python3.9/site-packages/django/template/defaulttags.py", line 168, in render
    len_values = len(values)
  File "/usr/local/lib/python3.9/site-packages/django/db/models/query.py", line 262, in __len__
    self._fetch_all()
  File "/usr/local/lib/python3.9/site-packages/django/db/models/query.py", line 1324, in _fetch_all
    self._result_cache = list(self._iterable_class(self))
  File "/usr/local/lib/python3.9/site-packages/django/db/models/query.py", line 51, in __iter__
    results = compiler.execute_sql(chunked_fetch=self.chunked_fetch, chunk_size=self.chunk_size)
  File "/usr/local/lib/python3.9/site-packages/django/db/models/sql/compiler.py", line 1175, in execute_sql
    cursor.execute(sql, params)
  File "/usr/local/lib/python3.9/site-packages/django/db/backends/utils.py", line 98, in execute
    return super().execute(sql, params)
  File "/usr/local/lib/python3.9/site-packages/django/db/backends/utils.py", line 66, in execute
    return self._execute_with_wrappers(sql, params, many=False, executor=self._execute)
  File "/usr/local/lib/python3.9/site-packages/django/db/backends/utils.py", line 75, in _execute_with_wrappers
    return executor(sql, params, many, context)
  File "/usr/local/lib/python3.9/site-packages/django/db/backends/utils.py", line 84, in _execute
    return self.cursor.execute(sql, params)
  File "/usr/local/lib/python3.9/site-packages/django/db/utils.py", line 90, in __exit__
    raise dj_exc_value.with_traceback(traceback) from exc_value
  File "/usr/local/lib/python3.9/site-packages/django/db/backends/utils.py", line 84, in _execute
    return self.cursor.execute(sql, params)
  File "/usr/local/lib/python3.9/site-packages/django/db/backends/mysql/base.py", line 73, in execute
    return self.cursor.execute(query, args)
  File "/usr/local/lib/python3.9/site-packages/pymysql/cursors.py", line 148, in execute
    result = self._query(query)
  File "/usr/local/lib/python3.9/site-packages/pymysql/cursors.py", line 310, in _query
    conn.query(q)
  File "/usr/local/lib/python3.9/site-packages/pymysql/connections.py", line 548, in query
    self._affected_rows = self._read_query_result(unbuffered=unbuffered)
  File "/usr/local/lib/python3.9/site-packages/pymysql/connections.py", line 775, in _read_query_result
    result.read()
  File "/usr/local/lib/python3.9/site-packages/pymysql/connections.py", line 1156, in read
    first_packet = self.connection._read_packet()
  File "/usr/local/lib/python3.9/site-packages/pymysql/connections.py", line 725, in _read_packet
    packet.raise_for_error()
  File "/usr/local/lib/python3.9/site-packages/pymysql/protocol.py", line 221, in raise_for_error
    err.raise_mysql_exception(self._data)
  File "/usr/local/lib/python3.9/site-packages/pymysql/err.py", line 143, in raise_mysql_exception
    raise errorclass(errno, errval)
django.db.utils.ProgrammingError: (1146, "Table 'il-piccola-0001_checkpassword.app_member' doesn't exist")
2021-05-14 10:15:14,597 [WARNING] Not Found: /favicon.ico
